<?xml version="1.0"?>

<sdf version="1.6">
  <model name="MiR100">
    <plugin name="slotcar" filename="libslotcar.so">

      <nominal_drive_speed>0.7</nominal_drive_speed>
      <nominal_drive_acceleration>0.5</nominal_drive_acceleration>
      <max_drive_acceleration>0.75</max_drive_acceleration>

      <nominal_turn_speed>0.3</nominal_turn_speed>
      <nominal_turn_acceleration>1.5</nominal_turn_acceleration>
      <max_turn_acceleration>2.0</max_turn_acceleration>

      <tire_radius>0.1</tire_radius>
      <base_width>0.3206</base_width>

      <stop_distance>0.70</stop_distance>
      <stop_radius>0.70</stop_radius>

      <!-- Battery params -->
      <nominal_voltage>12.0</nominal_voltage>
      <nominal_capacity>24.0</nominal_capacity>
      <charging_current>5.0</charging_current>

      <!-- Physical params -->
      <mass>20.0</mass>
      <inertia>10.0</inertia>
      <friction_coefficient>0.22</friction_coefficient>

      <!-- Power systems -->
      <nominal_power>20.0</nominal_power>

    </plugin>
  
    <link name="body">
      <pose>0 0 0 0 0 0</pose>

      <inertial>
        <pose>0 0 0.43294142 0 0 0</pose>
        <mass>244.816489</mass>
        <inertia>
          <ixx>29.0695006</ixx>
          <iyy>26.0429852</iyy>
          <izz>23.0523441</izz>
        </inertia>
      </inertial>

      <visual name="body_visual">
        <geometry>
          <mesh><uri>model://MiR100/meshes/body.obj</uri></mesh>
        </geometry>
      </visual>
      <collision name="body_collision">
        <geometry>
          <mesh><uri>model://MiR100/meshes/body.obj</uri></mesh>
        </geometry>
      </collision>

      <visual name="WheelLeftFront">
        <pose>0.262 0.220 0.061 0 0 0</pose>
        <geometry>
          <mesh>
            <uri>model://MiR100/meshes/WheelMain.obj</uri>
          </mesh>
        </geometry>
      </visual>
      <collision name="front_caster_left">
        <pose>.27 .25 0.05 0 0 0</pose>
        <geometry>
          <sphere><radius>0.05</radius></sphere>
        </geometry>
        <surface>
          <friction>
            <torsional>
              <coefficient>0.0</coefficient>
            </torsional>
            <ode>
              <mu>0.0</mu>
              <mu2>0.0</mu2>
            </ode>
            <bullet>
              <friction>0.0</friction>
              <friction2>0.0</friction2>
              <rolling_friction>0.0</rolling_friction>
            </bullet>
          </friction>
        </surface>
      </collision>

      <visual name="WheelLeftBack">
        <pose>-0.334 0.220 0.061 0 0 0</pose>
        <geometry>
          <mesh>
            <uri>model://MiR100/meshes/WheelMain.obj</uri>
          </mesh>
        </geometry>
      </visual>
      <collision name="back_caster_left">
        <pose>-.34 .25 0.05 0 0 0</pose>
        <geometry>
          <sphere><radius>0.05</radius></sphere>
        </geometry>
        <surface>
          <friction>
            <torsional>
              <coefficient>0.0</coefficient>
            </torsional>
            <ode>
              <mu>0.0</mu>
              <mu2>0.0</mu2>
            </ode>
            <bullet>
              <friction>0.0</friction>
              <friction2>0.0</friction2>
              <rolling_friction>0.0</rolling_friction>
            </bullet>
          </friction>
        </surface>
      </collision>

      <visual name="WheelRightFront">
        <pose>0.262 -0.217 0.061 0 0 0</pose>
        <geometry>
          <mesh>
            <uri>model://MiR100/meshes/WheelMain.obj</uri>
          </mesh>
        </geometry>
      </visual>
      <collision name="front_caster_right">
        <pose>.27 -.25 0.05 0 0 0</pose>
        <geometry>
          <sphere><radius>0.05</radius></sphere>
        </geometry>
        <surface>
          <friction>
            <torsional>
              <coefficient>0.0</coefficient>
            </torsional>
            <ode>
              <mu>0.0</mu>
              <mu2>0.0</mu2>
            </ode>
            <bullet>
              <friction>0.0</friction>
              <friction2>0.0</friction2>
              <rolling_friction>0.0</rolling_friction>
            </bullet>
          </friction>
        </surface>
      </collision>

      <visual name="WheelRightBack">
        <pose>-0.334 -0.217 0.061 0 0 0</pose>
        <geometry>
          <mesh>
            <uri>model://MiR100/meshes/WheelMain.obj</uri>
          </mesh>
        </geometry>
      </visual>
      <collision name="back_caster_right">
        <pose>-.34 -.25 0.05 0 0 0</pose>
        <geometry>
          <sphere><radius>0.05</radius></sphere>
        </geometry>
        <surface>
          <friction>
            <torsional>
              <coefficient>0.0</coefficient>
            </torsional>
            <ode>
              <mu>0.0</mu>
              <mu2>0.0</mu2>
            </ode>
            <bullet>
              <friction>0.0</friction>
              <friction2>0.0</friction2>
              <rolling_friction>0.0</rolling_friction>
            </bullet>
          </friction>
        </surface>
      </collision>
    </link>

    <link name="suspension_tire_left">
      
      <pose>0 0.26 0.10 0 0 0</pose>
      <inertial>
        <mass>1.00</mass>
        <inertia>
          <ixx>1.00</ixx>
          <iyy>1.00</iyy>
          <izz>1.00</izz>
        </inertia>
      </inertial>
    </link>

    <joint name="joint_suspension_tire_left" type="prismatic">
      <parent>body</parent>
      <child>suspension_tire_left</child>
      <axis>
        <xyz>0 0 1</xyz>
        <dynamics>
          <damping>500</damping>
          <spring_reference>-0.09</spring_reference>
          <spring_stiffness>2000</spring_stiffness>
        </dynamics>
      </axis>
      <physics>
        <ode>
          <implicit_spring_damper>true</implicit_spring_damper>
        </ode>
      </physics>
    </joint>

    <link name="tire_left">
      <pose>0 0.26 0.10 0 0 0</pose>

      <inertial>
        <pose>0 0 0 0 0 0</pose>
        <mass>5.0</mass>
        
        
        
        
        <inertia>
          <ixx>0.757897446874</ixx>
          <iyy>1.302975553365</iyy>
          <izz>0.757897446874</izz>
        </inertia>
      </inertial>

      <visual name="WheelSideLeft">
        <pose>0.0 -0.032 0.0 0 0 0</pose>
        <geometry>
          <mesh>
            <uri>model://MiR100/meshes/WheelSide.obj</uri>
          </mesh>
        </geometry>
      </visual>
      <collision name="tire_left">
        <geometry>
          <sphere><radius>0.06137</radius></sphere>
        </geometry>
        <surface>
          <contact>
            <ode>
              <kp>10000000.0</kp>
              <kd>1.0</kd>
            </ode>
          </contact>
        </surface>
      </collision>
    </link>

    <joint name="joint_tire_left" type="revolute">
      <parent>suspension_tire_left</parent>
      <child>tire_left</child>
      <axis>
        <xyz>0 1 0</xyz>
      </axis>
    </joint>

    <link name="suspension_tire_right">
      
      <pose>0 -0.26 0.10 0 0 0</pose>
      <inertial>
        <mass>1.00</mass>
        <inertia>
          <ixx>1.00</ixx>
          <iyy>1.00</iyy>
          <izz>1.00</izz>
        </inertia>
      </inertial>
    </link>

    <joint name="joint_suspension_tire_right" type="prismatic">
      <parent>body</parent>
      <child>suspension_tire_right</child>
      <axis>
        <xyz>0 0 1</xyz>
        <dynamics>
          <damping>500</damping>
          <spring_reference>-0.09</spring_reference>
          <spring_stiffness>2000</spring_stiffness>
        </dynamics>
      </axis>
      <physics>
        <ode>
          <implicit_spring_damper>true</implicit_spring_damper>
        </ode>
      </physics>
    </joint>

    <link name="tire_right">
      <pose>0 -0.26 0.10 0 0 0</pose>

      <inertial>
        <pose>0 0 0 0 0 0</pose>
        
        <mass>5.0</mass>
        
        
        
        <inertia>
          <ixx>0.757897446874</ixx>
          <iyy>1.302975553365</iyy>
          <izz>0.757897446874</izz>
        </inertia>
      </inertial>

      <visual name="WheelSideRight">
        <pose>0.0 0.032 0.0 0 0 0</pose>
        <geometry>
          <mesh>
            <uri>model://MiR100/meshes/WheelSide.obj</uri>
          </mesh>
        </geometry>
      </visual>
      <collision name="tire_right">
        <geometry>
          <sphere><radius>0.06137</radius></sphere>
        </geometry>
        <surface>
          <contact>
            <ode>
              <kp>10000000.0</kp>
              <kd>1.0</kd>
            </ode>
          </contact>
        </surface>
      </collision>
    </link>

    <joint name="joint_tire_right" type="revolute">
      <parent>suspension_tire_right</parent>
      <child>tire_right</child>
      <axis>
        <xyz>0 1 0</xyz>
      </axis>
    </joint>
  </model>
</sdf>
